Workbook

Sheet Parametros
A1: Módulo de Cobertura Predictiva y Ritmo de Ejecución
A3: Parámetro | B3: Valor | C3: Descripción
A4: Meta cobertura | B4: 0.9 | C4: Meta mínima de médicos únicos cubiertos por ciclo
A5: Ciclo | B5: 2026-06 | C5: Identificador del ciclo promocional
A6: Fecha inicio ciclo | B6: 46174 | C6: Inicio del ciclo promocional
A7: Fecha fin ciclo | B7: 46198 | C7: Fin del ciclo. Configurado para 19 días hábiles.
A8: Fecha de corte | B8: 46185 | C8: Fecha editable para recalcular avance, atrasos y requerimientos diarios
A9: Días hábiles del ciclo | B9: =NETWORKDAYS(B6,B7,B17:B25) -> 19 | C9: Debe dar 19. Se calcula con NETWORKDAYS.
A10: Ciclos por año | B10: 12 | C10: Cantidad de ciclos promocionales en el año
A12: Regla de cálculo clave
A13: Contactos diarios requeridos | B13: Objetivo diario base + recuperación diaria de contactos dejados de hacer | C13: Los contactos no realizados al corte se reparten en los días hábiles restantes.
A14: Aceleración requerida | B14: Médicos dejados de ver / días hábiles restantes | C14: Indica cuántos médicos adicionales diarios debe ver el VM para llegar a cobertura.
A16: Feriados / días no hábiles | B16: Fecha | C16: Nota
A27: Nota para Moisés
A28: 1 | B28: El ciclo está configurado a 19 días hábiles. | C28: Cambiar fechas o feriados modifica automáticamente los días del ciclo.
A29: 2 | B29: La cobertura usa médicos únicos. | C29: Las visitas repetidas al mismo médico no incrementan cobertura.
A30: 3 | B30: El PSP/contactos usa conteo total. | C30: Las visitas repetidas sí cuentan como contactos.
A31: 4 | B31: La columna N del dashboard contiene la lectura accionable. | C31: Explica el nuevo número diario como objetivo + recuperación de contactos dejados de hacer.

Sheet Dashboard GD
A1: Dashboard GD - Cobertura Predictiva con Recuperación de Atrasos
A3: Fecha de corte | B3: =Parametros!$B$8 -> 46185 | C3: Cambiar en Parametros!B8 | E3: Ciclo | F3: =Parametros!$B$5 -> 2026-06 | G3: Días hábiles ciclo | H3: =Parametros!$B$9 -> 19 | I3: Meta cobertura | J3: =Parametros!$B$4 -> 0.9
A4: Regla clave | B4: Contactos diarios requeridos = objetivo diario base + contactos dejados de hacer repartidos en días restantes
A6: VM | B6: Médicos Prog. | C6: Visitados únicos | D6: Cobertura actual | E6: Proyección cierre | F6: Meta | G6: Obj. contactos diarios | H6: Contactos realizados | I6: Contactos dejados de hacer | J6: Contactos diarios requeridos | K6: Médicos dejados de ver | L6: Médicos diarios requeridos | M6: Aceleración requerida | N6: Mensaje / lectura accionable
A7: =Motor_Formulas!B4 -> Ana Martínez | B7: =Motor_Formulas!J4 -> 0 | C7: =Motor_Formulas!L4 -> 70 | D7: =Motor_Formulas!Z4 -> 0 | E7: =Motor_Formulas!AA4 -> 0 | F7: =Motor_Formulas!H4 -> 0.9 | G7: =Motor_Formulas!V4 -> 0 | H7: =Motor_Formulas!M4 -> 0 | I7: =Motor_Formulas!X4 -> 0 | J7: =Motor_Formulas!Y4 -> 0 | K7: =Motor_Formulas!S4 -> 0 | L7: =Motor_Formulas!U4 -> 0 | M7: =CEILING(Motor_Formulas!T4,1) -> 0 | N7: =Motor_Formulas!AD4 -> Su número de contactos diario requerido es 0. Este número es la suma del objetivo diario base (0.0) + los contactos dejados de hacer (0.0) repartidos en 9 días hábiles restantes. Para cobertura debe ver 0 médicos diarios; aceleración requerida: +0 médicos adicionales/día.
A8: =Motor_Formulas!B5 -> Carlos Pérez | B8: =Motor_Formulas!J5 -> 0 | C8: =Motor_Formulas!L5 -> 90 | D8: =Motor_Formulas!Z5 -> 0 | E8: =Motor_Formulas!AA5 -> 0 | F8: =Motor_Formulas!H5 -> 0.9 | G8: =Motor_Formulas!V5 -> 0 | H8: =Motor_Formulas!M5 -> 0 | I8: =Motor_Formulas!X5 -> 0 | J8: =Motor_Formulas!Y5 -> 0 | K8: =Motor_Formulas!S5 -> 0 | L8: =Motor_Formulas!U5 -> 0 | M8: =CEILING(Motor_Formulas!T5,1) -> 0 | N8: =Motor_Formulas!AD5 -> Su número de contactos diario requerido es 0. Este número es la suma del objetivo diario base (0.0) + los contactos dejados de hacer (0.0) repartidos en 9 días hábiles restantes. Para cobertura debe ver 0 médicos diarios; aceleración requerida: +0 médicos adicionales/día.
A9: =Motor_Formulas!B6 -> Laura Gómez | B9: =Motor_Formulas!J6 -> 0 | C9: =Motor_Formulas!L6 -> 85 | D9: =Motor_Formulas!Z6 -> 0 | E9: =Motor_Formulas!AA6 -> 0 | F9: =Motor_Formulas!H6 -> 0.9 | G9: =Motor_Formulas!V6 -> 0 | H9: =Motor_Formulas!M6 -> 0 | I9: =Motor_Formulas!X6 -> 0 | J9: =Motor_Formulas!Y6 -> 0 | K9: =Motor_Formulas!S6 -> 0 | L9: =Motor_Formulas!U6 -> 0 | M9: =CEILING(Motor_Formulas!T6,1) -> 0 | N9: =Motor_Formulas!AD6 -> Su número de contactos diario requerido es 0. Este número es la suma del objetivo diario base (0.0) + los contactos dejados de hacer (0.0) repartidos en 9 días hábiles restantes. Para cobertura debe ver 0 médicos diarios; aceleración requerida: +0 médicos adicionales/día.
A12: Cómo leer la aceleración
A13: Obj. contactos diarios | B13: Meta de contactos del ciclo dividida entre 19 días hábiles.
A14: Contactos dejados de hacer | B14: Diferencia entre lo que debería llevar al corte y lo que realmente hizo.
A15: Contactos diarios requeridos | B15: Nuevo número diario: objetivo diario base + recuperación de contactos dejados de hacer.
A16: Aceleración requerida | B16: Cuántos médicos adicionales por día debe ver para recuperar los médicos dejados de ver y llegar al 90%.

Sheet Motor_Formulas
A1: Motor técnico de cálculo - Ciclo de 19 días hábiles
A3: VM ID | B3: Nombre VM | C3: Línea | D3: Ciclo | E3: Fecha inicio | F3: Fecha fin | G3: Fecha corte | H3: Meta cobertura | I3: Meta contactos ciclo | J3: Médicos programados | K3: Médicos requeridos meta | L3: Médicos únicos visitados | M3: Contactos realizados | N3: Días hábiles ciclo | O3: Días hábiles transcurridos | P3: Días hábiles restantes | Q3: Objetivo médicos diarios | R3: Médicos esperados al corte | S3: Médicos dejados de ver | T3: Aceleración requerida | U3: Médicos diarios requeridos | V3: Objetivo contactos diarios | W3: Contactos esperados al corte | X3: Contactos dejados de hacer | Y3: Contactos diarios requeridos | Z3: Cobertura actual | AA3: Cobertura proyectada | AB3: Estado cobertura | AC3: Estado PSP | AD3: Lectura GD
A4: VM01 | B4: Ana Martínez | C4: Cardio Metabólica | D4: 2026-06 | E4: =Parametros!$B$6 -> 46174 | F4: =Parametros!$B$7 -> 46198 | G4: =Parametros!$B$8 -> 46185 | H4: =Parametros!$B$4 -> 0.9 | I4: =J4 -> 0 | J4: =COUNTIFS(Target_Medicos!$B$2:$B$2801,$A4,Target_Medicos!$I$2:$I$2801,1) -> 0 | K4: =CEILING(J4*H4,1) -> 0 | L4: 70 | M4: =COUNTIFS(Fact_Visitas!$D$2:$D$2801,$A4,Fact_Visitas!$B$2:$B$2801,"<="&$G4,Fact_Visitas!$G$2:$G$2801,"Realizada") -> 0 | N4: =Parametros!$B$9 -> 19 | O4: =IF($G4<$E4,0,NETWORKDAYS($E4,MIN($G4,$F4),Parametros!$B$17:$B$25)) -> 10 | P4: =MAX(0,$N4-$O4) -> 9 | Q4: =IFERROR($K4/$N4,0) -> 0 | R4: =$Q4*$O4 -> 0 | S4: =MAX(0,$R4-$L4) -> 0 | T4: =IF($P4>0,$S4/$P4,0) -> 0 | U4: =IF($P4>0,CEILING($Q4+$T4,1),0) -> 0 | V4: =IFERROR($I4/$N4,0) -> 0 | W4: =$V4*$O4 -> 0 | X4: =MAX(0,$W4-$M4) -> 0 | Y4: =IF($P4>0,CEILING($V4+($X4/$P4),1),0) -> 0 | Z4: =IFERROR($L4/$J4,0) -> 0 | AA4: =MIN(1,IFERROR(($L4/$O4*$N4)/$J4,0)) -> 0 | AB4: =IF($AA4>=$H4,"Verde",IF($AA4>=0.85,"Amarillo","Rojo")) -> Rojo | AC4: =IF(($M4/$O4*$N4)>=$I4,"Verde",IF(($M4/$O4*$N4)>=$I4*0.9,"Amarillo","Rojo")) -> Verde | AD4: ="Su número de contactos diario requerido es "&$Y4&". Este número es la suma del objetivo diario base ("&TEXT($V4,"0.0")&") + los contactos dejados de hacer ("&TEXT($X4,"0.0")&") repartidos en "&$P4&" días hábiles restantes. Para cobertura debe ver "&$U4&" médicos diarios; aceleración requerida: +"&CEILING($T4,1)&" médicos adicionales/día." -> Su número de contactos diario requerido es 0. Este número es la suma del objetivo diario base (0.0) + los contactos dejados de hacer (0.0) repartidos en 9 días hábiles restantes. Para cobertura debe ver 0 médicos diarios; aceleración requerida: +0 médicos adicionales/día.
A5: VM02 | B5: Carlos Pérez | C5: Cardio Metabólica | D5: 2026-06 | E5: =Parametros!$B$6 -> 46174 | F5: =Parametros!$B$7 -> 46198 | G5: =Parametros!$B$8 -> 46185 | H5: =Parametros!$B$4 -> 0.9 | I5: =J5 -> 0 | J5: =COUNTIFS(Target_Medicos!$B$2:$B$2801,$A5,Target_Medicos!$I$2:$I$2801,1) -> 0 | K5: =CEILING(J5*H5,1) -> 0 | L5: 90 | M5: =COUNTIFS(Fact_Visitas!$D$2:$D$2801,$A5,Fact_Visitas!$B$2:$B$2801,"<="&$G5,Fact_Visitas!$G$2:$G$2801,"Realizada") -> 0 | N5: =Parametros!$B$9 -> 19 | O5: =IF($G5<$E5,0,NETWORKDAYS($E5,MIN($G5,$F5),Parametros!$B$17:$B$25)) -> 10 | P5: =MAX(0,$N5-$O5) -> 9 | Q5: =IFERROR($K5/$N5,0) -> 0 | R5: =$Q5*$O5 -> 0 | S5: =MAX(0,$R5-$L5) -> 0 | T5: =IF($P5>0,$S5/$P5,0) -> 0 | U5: =IF($P5>0,CEILING($Q5+$T5,1),0) -> 0 | V5: =IFERROR($I5/$N5,0) -> 0 | W5: =$V5*$O5 -> 0 | X5: =MAX(0,$W5-$M5) -> 0 | Y5: =IF($P5>0,CEILING($V5+($X5/$P5),1),0) -> 0 | Z5: =IFERROR($L5/$J5,0) -> 0 | AA5: =MIN(1,IFERROR(($L5/$O5*$N5)/$J5,0)) -> 0 | AB5: =IF($AA5>=$H5,"Verde",IF($AA5>=0.85,"Amarillo","Rojo")) -> Rojo | AC5: =IF(($M5/$O5*$N5)>=$I5,"Verde",IF(($M5/$O5*$N5)>=$I5*0.9,"Amarillo","Rojo")) -> Verde | AD5: ="Su número de contactos diario requerido es "&$Y5&". Este número es la suma del objetivo diario base ("&TEXT($V5,"0.0")&") + los contactos dejados de hacer ("&TEXT($X5,"0.0")&") repartidos en "&$P5&" días hábiles restantes. Para cobertura debe ver "&$U5&" médicos diarios; aceleración requerida: +"&CEILING($T5,1)&" médicos adicionales/día." -> Su número de contactos diario requerido es 0. Este número es la suma del objetivo diario base (0.0) + los contactos dejados de hacer (0.0) repartidos en 9 días hábiles restantes. Para cobertura debe ver 0 médicos diarios; aceleración requerida: +0 médicos adicionales/día.
A6: VM03 | B6: Laura Gómez | C6: Cardio Metabólica | D6: 2026-06 | E6: =Parametros!$B$6 -> 46174 | F6: =Parametros!$B$7 -> 46198 | G6: =Parametros!$B$8 -> 46185 | H6: =Parametros!$B$4 -> 0.9 | I6: =J6 -> 0 | J6: =COUNTIFS(Target_Medicos!$B$2:$B$2801,$A6,Target_Medicos!$I$2:$I$2801,1) -> 0 | K6: =CEILING(J6*H6,1) -> 0 | L6: 85 | M6: =COUNTIFS(Fact_Visitas!$D$2:$D$2801,$A6,Fact_Visitas!$B$2:$B$2801,"<="&$G6,Fact_Visitas!$G$2:$G$2801,"Realizada") -> 0 | N6: =Parametros!$B$9 -> 19 | O6: =IF($G6<$E6,0,NETWORKDAYS($E6,MIN($G6,$F6),Parametros!$B$17:$B$25)) -> 10 | P6: =MAX(0,$N6-$O6) -> 9 | Q6: =IFERROR($K6/$N6,0) -> 0 | R6: =$Q6*$O6 -> 0 | S6: =MAX(0,$R6-$L6) -> 0 | T6: =IF($P6>0,$S6/$P6,0) -> 0 | U6: =IF($P6>0,CEILING($Q6+$T6,1),0) -> 0 | V6: =IFERROR($I6/$N6,0) -> 0 | W6: =$V6*$O6 -> 0 | X6: =MAX(0,$W6-$M6) -> 0 | Y6: =IF($P6>0,CEILING($V6+($X6/$P6),1),0) -> 0 | Z6: =IFERROR($L6/$J6,0) -> 0 | AA6: =MIN(1,IFERROR(($L6/$O6*$N6)/$J6,0)) -> 0 | AB6: =IF($AA6>=$H6,"Verde",IF($AA6>=0.85,"Amarillo","Rojo")) -> Rojo | AC6: =IF(($M6/$O6*$N6)>=$I6,"Verde",IF(($M6/$O6*$N6)>=$I6*0.9,"Amarillo","Rojo")) -> Verde | AD6: ="Su número de contactos diario requerido es "&$Y6&". Este número es la suma del objetivo diario base ("&TEXT($V6,"0.0")&") + los contactos dejados de hacer ("&TEXT($X6,"0.0")&") repartidos en "&$P6&" días hábiles restantes. Para cobertura debe ver "&$U6&" médicos diarios; aceleración requerida: +"&CEILING($T6,1)&" médicos adicionales/día." -> Su número de contactos diario requerido es 0. Este número es la suma del objetivo diario base (0.0) + los contactos dejados de hacer (0.0) repartidos en 9 días hábiles restantes. Para cobertura debe ver 0 médicos diarios; aceleración requerida: +0 médicos adicionales/día.

Sheet Target_Medicos
A1: medico_id | B1: codigo_id | C1: nombre | D1: gerente_id | E1: linea_id | F1: Ciclo | G1: Especialidad | H1: potencial | I1: programado_flag
A2: MED_001 | B2: VM-1 | C2: FRANCIA MARTINEZ | D2: =VLOOKUP(tblTargetMedicos[[#This Row],[codigo_id]],[1]DIM_REPRESENTANTE_MEDICO!$C:$F,4,0) -> 12 | E2: =VLOOKUP(tblTargetMedicos[[#This Row],[codigo_id]],[1]DIM_REPRESENTANTE_MEDICO!$C:$F,3,0) -> 6 | F2: C06-2026 | G2: ENDOCRINOLOGOS | H2: B | I2: 1
A3: MED_002 | B3: VM-1 | C3: FRANCIA MARTINEZ | D3: =VLOOKUP(tblTargetMedicos[[#This Row],[codigo_id]],[1]DIM_REPRESENTANTE_MEDICO!$C:$F,4,0) -> 12 | E3: =VLOOKUP(tblTargetMedicos[[#This Row],[codigo_id]],[1]DIM_REPRESENTANTE_MEDICO!$C:$F,3,0) -> 6 | F3: C06-2026 | G3: GERIATRA | H3: B | I3: 1
A4: MED_003 | B4: VM-1 | C4: FRANCIA MARTINEZ | D4: =VLOOKUP(tblTargetMedicos[[#This Row],[codigo_id]],[1]DIM_REPRESENTANTE_MEDICO!$C:$F,4,0) -> 12 | E4: =VLOOKUP(tblTargetMedicos[[#This Row],[codigo_id]],[1]DIM_REPRESENTANTE_MEDICO!$C:$F,3,0) -> 6 | F4: C06-2026 | G4: MEDICINA FAMILIAR | H4: B | I4: 1
A5: MED_004 | B5: VM-1 | C5: FRANCIA MARTINEZ | D5: =VLOOKUP(tblTargetMedicos[[#This Row],[codigo_id]],[1]DIM_REPRESENTANTE_MEDICO!$C:$F,4,0) -> 12 | E5: =VLOOKUP(tblTargetMedicos[[#This Row],[codigo_id]],[1]DIM_REPRESENTANTE_MEDICO!$C:$F,3,0) -> 6 | F5: C06-2026 | G5: MEDICINA FAMILIAR | H5: B | I5: 1
A6: MED_005 | B6: VM-1 | C6: FRANCIA MARTINEZ | D6: =VLOOKUP(tblTargetMedicos[[#This Row],[codigo_id]],[1]DIM_REPRESENTANTE_MEDICO!$C:$F,4,0) -> 12 | E6: =VLOOKUP(tblTargetMedicos[[#This Row],[codigo_id]],[1]DIM_REPRESENTANTE_MEDICO!$C:$F,3,0) -> 6 | F6: C06-2026 | G6: ENDOCRINOLOGOS | H6: B | I6: 1
A7: MED_006 | B7: VM-1 | C7: FRANCIA MARTINEZ | D7: =VLOOKUP(tblTargetMedicos[[#This Row],[codigo_id]],[1]DIM_REPRESENTANTE_MEDICO!$C:$F,4,0) -> 12 | E7: =VLOOKUP(tblTargetMedicos[[#This Row],[codigo_id]],[1]DIM_REPRESENTANTE_MEDICO!$C:$F,3,0) -> 6 | F7: C06-2026 | G7: MEDICINA FAMILIAR | H7: B | I7: 1
A8: MED_007 | B8: VM-1 | C8: FRANCIA MARTINEZ | D8: =VLOOKUP(tblTargetMedicos[[#This Row],[codigo_id]],[1]DIM_REPRESENTANTE_MEDICO!$C:$F,4,0) -> 12 | E8: =VLOOKUP(tblTargetMedicos[[#This Row],[codigo_id]],[1]DIM_REPRESENTANTE_MEDICO!$C:$F,3,0) -> 6 | F8: C06-2026 | G8: DIABETOLOGOS | H8: B | I8: 1
A9: MED_008 | B9: VM-1 | C9: FRANCIA MARTINEZ | D9: =VLOOKUP(tblTargetMedicos[[#This Row],[codigo_id]],[1]DIM_REPRESENTANTE_MEDICO!$C:$F,4,0) -> 12 | E9: =VLOOKUP(tblTargetMedicos[[#This Row],[codigo_id]],[1]DIM_REPRESENTANTE_MEDICO!$C:$F,3,0) -> 6 | F9: C06-2026 | G9: MEDICINA FAMILIAR | H9: B | I9: 1
A10: MED_009 | B10: VM-1 | C10: FRANCIA MARTINEZ | D10: =VLOOKUP(tblTargetMedicos[[#This Row],[codigo_id]],[1]DIM_REPRESENTANTE_MEDICO!$C:$F,4,0) -> 12 | E10: =VLOOKUP(tblTargetMedicos[[#This Row],[codigo_id]],[1]DIM_REPRESENTANTE_MEDICO!$C:$F,3,0) -> 6 | F10: C06-2026 | G10: GERIATRA | H10: B | I10: 1
A11: MED_010 | B11: VM-1 | C11: FRANCIA MARTINEZ | D11: =VLOOKUP(tblTargetMedicos[[#This Row],[codigo_id]],[1]DIM_REPRESENTANTE_MEDICO!$C:$F,4,0) -> 12 | E11: =VLOOKUP(tblTargetMedicos[[#This Row],[codigo_id]],[1]DIM_REPRESENTANTE_MEDICO!$C:$F,3,0) -> 6 | F11: C06-2026 | G11: MEDICINA FAMILIAR | H11: B | I11: 1
A12: MED_011 | B12: VM-1 | C12: FRANCIA MARTINEZ | D12: =VLOOKUP(tblTargetMedicos[[#This Row],[codigo_id]],[1]DIM_REPRESENTANTE_MEDICO!$C:$F,4,0) -> 12 | E12: =VLOOKUP(tblTargetMedicos[[#This Row],[codigo_id]],[1]DIM_REPRESENTANTE_MEDICO!$C:$F,3,0) -> 6 | F12: C06-2026 | G12: MEDICINA INTERNA | H12: B | I12: 1
A13: MED_012 | B13: VM-1 | C13: FRANCIA MARTINEZ | D13: =VLOOKUP(tblTargetMedicos[[#This Row],[codigo_id]],[1]DIM_REPRESENTANTE_MEDICO!$C:$F,4,0) -> 12 | E13: =VLOOKUP(tblTargetMedicos[[#This Row],[codigo_id]],[1]DIM_REPRESENTANTE_MEDICO!$C:$F,3,0) -> 6 | F13: C06-2026 | G13: MEDICINA FAMILIAR | H13: B | I13: 1
... A2801: MED_2800 | B2801: VM-14 | C2801: LUIS GOMEZ | D2801: =VLOOKUP(tblTargetMedicos[[#This Row],[codigo_id]],[1]DIM_REPRESENTANTE_MEDICO!$C:$F,4,0) -> 8 | E2801: =VLOOKUP(tblTargetMedicos[[#This Row],[codigo_id]],[1]DIM_REPRESENTANTE_MEDICO!$C:$F,3,0) -> 8 | F2801: C06-2026 | G2801: DIABETOLOGOS | H2801: C | I2801: 1

Sheet Fact_Visitas
A1: visita_id | B1: fecha_visita | C1: Ciclo | D1: codigo_id | E1: medico_id | F1: tipo_contacto | G1: estado_visita | H1: producto_foco
A2: VIS_0001 | B2: 46174 | C2: C03-2026 | D2: VM-1 | E2: MED_001 | F2: Presencial | G2: Realizada | H2: Producto foco
A3: VIS_0002 | B3: 46175 | C3: C03-2026 | D3: VM-1 | E3: MED_002 | F3: Presencial | G3: Realizada | H3: Producto foco
A4: VIS_0003 | B4: 46176 | C4: C03-2026 | D4: VM-1 | E4: MED_003 | F4: Presencial | G4: Realizada | H4: Producto foco
A5: VIS_0004 | B5: 46177 | C5: C03-2026 | D5: VM-1 | E5: MED_004 | F5: Presencial | G5: Realizada | H5: Producto foco
A6: VIS_0005 | B6: 46178 | C6: C03-2026 | D6: VM-1 | E6: MED_005 | F6: Presencial | G6: Realizada | H6: Producto foco
A7: VIS_0006 | B7: 46181 | C7: C03-2026 | D7: VM-1 | E7: MED_006 | F7: Presencial | G7: Realizada | H7: Producto foco
A8: VIS_0007 | B8: 46182 | C8: C03-2026 | D8: VM-1 | E8: MED_007 | F8: Presencial | G8: Realizada | H8: Producto foco
A9: VIS_0008 | B9: 46183 | C9: C03-2026 | D9: VM-1 | E9: MED_008 | F9: Presencial | G9: Realizada | H9: Producto foco
A10: VIS_0009 | B10: 46184 | C10: C03-2026 | D10: VM-1 | E10: MED_009 | F10: Presencial | G10: Realizada | H10: Producto foco
A11: VIS_0010 | B11: 46185 | C11: C03-2026 | D11: VM-1 | E11: MED_010 | F11: Presencial | G11: Realizada | H11: Producto foco
A12: VIS_0011 | B12: 46174 | C12: C03-2026 | D12: VM-1 | E12: MED_011 | F12: Presencial | G12: Realizada | H12: Producto foco
A13: VIS_0012 | B13: 46175 | C13: C03-2026 | D13: VM-1 | E13: MED_012 | F13: Presencial | G13: Realizada | H13: Producto foco
... A100: VIS_0099 | B100: 46184 | C100: C03-2026 | D100: VM-1 | E100: MED_099 | F100: Presencial | G100: Realizada | H100: Producto foco
A101: VIS_0100 | B101: 46185 | C101: C03-2026 | D101: VM-1 | E101: MED_100 | F101: Presencial
A102: VIS_0101 | B102: 46174 | C102: C03-2026 | D102: VM-1 | E102: MED_101 | F102: Presencial
A103: VIS_0102 | B103: 46175 | C103: C03-2026 | D103: VM-1 | E103: MED_102 | F103: Presencial
A104: VIS_0103 | B104: 46176 | C104: C03-2026 | D104: VM-1 | E104: MED_103 | F104: Presencial
A105: VIS_0104 | B105: 46177 | C105: C03-2026 | D105: VM-1 | E105: MED_104 | F105: Presencial
A106: VIS_0105 | B106: 46178 | C106: C03-2026 | D106: VM-1 | E106: MED_105 | F106: Presencial
A107: VIS_0106 | B107: 46181 | C107: C03-2026 | D107: VM-1 | E107: MED_106 | F107: Presencial
A108: VIS_0107 | B108: 46182 | C108: C03-2026 | D108: VM-1 | E108: MED_107 | F108: Presencial
A109: VIS_0108 | B109: 46183 | C109: C03-2026 | D109: VM-1 | E109: MED_108 | F109: Presencial
A110: VIS_0109 | B110: 46184 | C110: C03-2026 | D110: VM-1 | E110: MED_109 | F110: Presencial
A111: VIS_0110 | B111: 46185 | C111: C03-2026 | D111: VM-1 | E111: MED_110 | F111: Presencial
A112: VIS_0111 | B112: 46174 | C112: C03-2026 | D112: VM-1 | E112: MED_111 | F112: Presencial
... A187: VIS_0186 | B187: 46181 | C187: C03-2026 | D187: VM-1 | E187: MED_186 | F187: Presencial
A188: VIS_0187 | B188: 46182 | C188: C03-2026 | D188: VM-1 | E188: MED_187 | F188: Presencial | L188: =198/2 -> 99
A189: VIS_0188 | B189: 46183 | C189: C03-2026 | D189: VM-1 | E189: MED_188 | F189: Presencial
A190: VIS_0189 | B190: 46184 | C190: C03-2026 | D190: VM-1 | E190: MED_189 | F190: Presencial
A191: VIS_0190 | B191: 46185 | C191: C03-2026 | D191: VM-1 | E191: MED_190 | F191: Presencial
A192: VIS_0191 | B192: 46174 | C192: C03-2026 | D192: VM-1 | E192: MED_191 | F192: Presencial
A193: VIS_0192 | B193: 46175 | C193: C03-2026 | D193: VM-1 | E193: MED_192 | F193: Presencial
A194: VIS_0193 | B194: 46176 | C194: C03-2026 | D194: VM-1 | E194: MED_193 | F194: Presencial
A195: VIS_0194 | B195: 46177 | C195: C03-2026 | D195: VM-1 | E195: MED_194 | F195: Presencial
A196: VIS_0195 | B196: 46178 | C196: C03-2026 | D196: VM-1 | E196: MED_195 | F196: Presencial
A197: VIS_0196 | B197: 46181 | C197: C03-2026 | D197: VM-1 | E197: MED_196 | F197: Presencial
A198: VIS_0197 | B198: 46182 | C198: C03-2026 | D198: VM-1 | E198: MED_197 | F198: Presencial
A199: VIS_0198 | B199: 46183 | C199: C03-2026 | D199: VM-2 | E199: MED_198 | F199: Presencial | G199: Realizada | H199: Producto foco
A200: VIS_0199 | B200: 46184 | C200: C03-2026 | D200: VM-2 | E200: MED_199 | F200: Presencial | G200: Realizada | H200: Producto foco
...

Sheet Diccionario
A1: Campo | B1: Hoja | C1: Descripción | D1: Fórmula / lógica | E1: Uso GD | F1: Nota Moisés
A2: Días hábiles ciclo | B2: Parametros | C2: Duración del ciclo configurada a 19 días hábiles | D2: NETWORKDAYS(fecha_inicio, fecha_fin, feriados) | E2: Define el tiempo real disponible para cumplir cobertura | F2: Debe quedar parametrizable por línea/ciclo
A3: Obj. contactos diarios | B3: Dashboard GD | C3: Meta de contactos del ciclo dividida entre 19 días hábiles | D3: Meta contactos ciclo / días hábiles ciclo | E3: Ritmo base que el VM debería sostener | F3: No incluye atrasos
A4: Contactos dejados de hacer | B4: Dashboard GD | C4: Contactos que debieron hacerse al corte y no se hicieron | D4: MAX(0, contactos esperados al corte - contactos realizados) | E4: Muestra atraso acumulado | F4: Es el atraso que se suma a los próximos días
A5: Contactos diarios requeridos | B5: Dashboard GD | C5: Nuevo número diario para cumplir el ciclo | D5: CEILING(objetivo diario + contactos dejados/días restantes, 1) | E5: Acción diaria concreta para el VM | F5: Esta es la columna crítica de recuperación
A6: Médicos dejados de ver | B6: Dashboard GD | C6: Médicos únicos que debieron estar cubiertos al corte y no lo están | D6: MAX(0, médicos esperados al corte - médicos únicos visitados) | E6: Muestra atraso real de cobertura | F6: Usa médicos únicos, no contactos totales
A7: Aceleración requerida | B7: Dashboard GD | C7: Médicos adicionales por día necesarios para recuperar el atraso | D7: CEILING(médicos dejados de ver / días restantes, 1) | E7: Indica cuántos médicos más debe ver diariamente | F7: No es la meta total diaria; es el extra sobre el ritmo base
A8: Médicos diarios requeridos | B8: Dashboard GD | C8: Número total de médicos únicos diarios que debe cubrir desde el corte | D8: CEILING(objetivo médicos diarios + aceleración, 1) | E8: Indica plan diario de cobertura | F8: Incluye base + recuperación
A9: Lectura accionable | B9: Dashboard GD columna N | C9: Mensaje ejecutivo para el GD | D9: Texto concatenado con fórmulas | E9: Convierte el KPI en conversación de seguimiento | F9: Debe mantenerse en español claro
